Workbook

Sheet Executive Summary
A1: Marketing Campaign Performance — Executive Summary
A2: Week of Dec 9 - Dec 15, 2024
A4: Portfolio KPIs
A5: Total Spend | B5: =SUM('Efficiency Analysis'!B11:B14) -> 104682.25
A6: Total Revenue | B6: =SUM('Efficiency Analysis'!C11:C14) -> 631975.86
A7: Overall ROAS | B7: =B6/B5 -> 6.0370871
A8: Total Net Profit | B8: =SUM('Efficiency Analysis'!J11:J14) -> 255518.06
A10: Key Findings
A11: • Email is the standout channel: near-zero cost per acquisition and a massive ROAS, though its spend base is tiny, so its dollar impact is small relative to Google/Facebook.
A12: • Google_Ads is the strongest paid-media performer — ROAS well above target and CPA well under the max, despite below-benchmark CTR.
A13: • Facebook_Ads is solidly profitable and clears target ROAS, but with less headroom than Google_Ads or Email.
A14: • TikTok_Ads is underwater: below-target ROAS, above-max CPA, and negative net profit for the week — the clear candidate for a spend cut.
A16: Reallocation Constraints
A17: Max Total Reallocation Limit | B17: 10000
A18: Max Per-Channel Increase | B18: 0.15
A19: Budget Reallocation — Classification & Calculations
A20: Channel | B20: Current Spend | C20: Conversions | D20: ROAS | E20: % of Target ROAS | F20: CPA | G20: % of Max CPA | H20: Net Profit | I20: Classification | J20: Decrease $ | K20: Proposed Increase $ | L20: Per-Channel Cap $ | M20: Capped Increase $
A21: Facebook_Ads | B21: ='Efficiency Analysis'!B11 -> 36678.01 | C21: ='Efficiency Analysis'!D11 -> 1674 | D21: ='Efficiency Analysis'!F11 -> 4.5117701 | E21: =D21/'Efficiency Analysis'!$B$5 -> 1.1279425 | F21: ='Efficiency Analysis'!H11 -> 21.9104 | G21: =F21/'Efficiency Analysis'!$B$6 -> 0.438208 | H21: ='Efficiency Analysis'!J11 -> 57493.777 | I21: =IF(C21<50,"INSUFFICIENT_DATA",IF(AND(E21<0.5,H21<=0),"DECREASE_HEAVY",IF(AND(G21>1.5,H21<=0),"DECREASE_HEAVY",IF(AND(E21<1,G21>1,H21<=0),"DECREASE_HEAVY",IF(AND(E21>=1.15,G21<=0.8,H21>0),"INCREASE",IF(E21<0.8,"DECREASE_LIGHT",IF(G21>1.2,"DECREASE_LIGHT","MAINTAIN"))))))) -> MAINTAIN | J21: =IF(I21="DECREASE_HEAVY",B21*0.45,IF(I21="DECREASE_LIGHT",B21*0.25,0)) -> 0 | K21: =(IF(I21="INCREASE",H21/SUMIF($I$21:$I$24,"INCREASE",$H$21:$H$24),0))*$B$26 -> 0 | L21: =B21*$B$18 -> 5501.7015 | M21: =IF(I21="INCREASE",MIN(K21,L21),0) -> 0
A22: Google_Ads | B22: ='Efficiency Analysis'!B12 -> 28184.51 | C22: ='Efficiency Analysis'!D12 -> 1651 | D22: ='Efficiency Analysis'!F12 -> 6.0464017 | E22: =D22/'Efficiency Analysis'!$B$5 -> 1.5116004 | F22: ='Efficiency Analysis'!H12 -> 17.071175 | G22: =F22/'Efficiency Analysis'!$B$6 -> 0.3414235 | H22: ='Efficiency Analysis'!J12 -> 69377.155 | I22: =IF(C22<50,"INSUFFICIENT_DATA",IF(AND(E22<0.5,H22<=0),"DECREASE_HEAVY",IF(AND(G22>1.5,H22<=0),"DECREASE_HEAVY",IF(AND(E22<1,G22>1,H22<=0),"DECREASE_HEAVY",IF(AND(E22>=1.15,G22<=0.8,H22>0),"INCREASE",IF(E22<0.8,"DECREASE_LIGHT",IF(G22>1.2,"DECREASE_LIGHT","MAINTAIN"))))))) -> INCREASE | J22: =IF(I22="DECREASE_HEAVY",B22*0.45,IF(I22="DECREASE_LIGHT",B22*0.25,0)) -> 0 | K22: =(IF(I22="INCREASE",H22/SUMIF($I$21:$I$24,"INCREASE",$H$21:$H$24),0))*$B$26 -> 5832.2658 | L22: =B22*$B$18 -> 4227.6765 | M22: =IF(I22="INCREASE",MIN(K22,L22),0) -> 4227.6765
A23: TikTok_Ads | B23: ='Efficiency Analysis'!B13 -> 37982.97 | C23: ='Efficiency Analysis'!D13 -> 663 | D23: ='Efficiency Analysis'!F13 -> 1.5387873 | E23: =D23/'Efficiency Analysis'!$B$5 -> 0.38469681 | F23: ='Efficiency Analysis'!H13 -> 57.289548 | G23: =F23/'Efficiency Analysis'!$B$6 -> 1.145791 | H23: ='Efficiency Analysis'!J13 -> -5295.9585 | I23: =IF(C23<50,"INSUFFICIENT_DATA",IF(AND(E23<0.5,H23<=0),"DECREASE_HEAVY",IF(AND(G23>1.5,H23<=0),"DECREASE_HEAVY",IF(AND(E23<1,G23>1,H23<=0),"DECREASE_HEAVY",IF(AND(E23>=1.15,G23<=0.8,H23>0),"INCREASE",IF(E23<0.8,"DECREASE_LIGHT",IF(G23>1.2,"DECREASE_LIGHT","MAINTAIN"))))))) -> DECREASE_HEAVY | J23: =IF(I23="DECREASE_HEAVY",B23*0.45,IF(I23="DECREASE_LIGHT",B23*0.25,0)) -> 17092.337 | K23: =(IF(I23="INCREASE",H23/SUMIF($I$21:$I$24,"INCREASE",$H$21:$H$24),0))*$B$26 -> 0 | L23: =B23*$B$18 -> 5697.4455 | M23: =IF(I23="INCREASE",MIN(K23,L23),0) -> 0
A24: Email | B24: ='Efficiency Analysis'!B14 -> 1836.76 | C24: ='Efficiency Analysis'!D14 -> 2335 | D24: ='Efficiency Analysis'!F14 -> 129.37484 | E24: =D24/'Efficiency Analysis'!$B$5 -> 32.34371 | F24: ='Efficiency Analysis'!H14 -> 0.78662099 | G24: =F24/'Efficiency Analysis'!$B$6 -> 0.01573242 | H24: ='Efficiency Analysis'!J14 -> 133943.08 | I24: =IF(C24<50,"INSUFFICIENT_DATA",IF(AND(E24<0.5,H24<=0),"DECREASE_HEAVY",IF(AND(G24>1.5,H24<=0),"DECREASE_HEAVY",IF(AND(E24<1,G24>1,H24<=0),"DECREASE_HEAVY",IF(AND(E24>=1.15,G24<=0.8,H24>0),"INCREASE",IF(E24<0.8,"DECREASE_LIGHT",IF(G24>1.2,"DECREASE_LIGHT","MAINTAIN"))))))) -> INCREASE | J24: =IF(I24="DECREASE_HEAVY",B24*0.45,IF(I24="DECREASE_LIGHT",B24*0.25,0)) -> 0 | K24: =(IF(I24="INCREASE",H24/SUMIF($I$21:$I$24,"INCREASE",$H$21:$H$24),0))*$B$26 -> 11260.071 | L24: =B24*$B$18 -> 275.514 | M24: =IF(I24="INCREASE",MIN(K24,L24),0) -> 275.514
A26: Freed Budget (from decreases) | B26: =SUM(J21:J24) -> 17092.337
A27: Scale Factor (limit / proposed capped increases) | B27: =IFERROR(MIN(1,$B$17/SUM(M21:M24)),1) -> 1
A28: Unallocated Reserve | B28: =$B$26-SUM(M21:M24)*$B$27 -> 12589.146
A30: Final Reallocation Table
A31: Channel | B31: Current Budget | C31: Change $ | D31: Change % | E31: New Budget | F31: Classification
A32: =A21 -> Facebook_Ads | B32: =B21 -> 36678.01 | C32: =M21*$B$27-J21 -> 0 | D32: =C32/B32 -> 0 | E32: =B32+C32 -> 36678.01 | F32: =I21 -> MAINTAIN
A33: =A22 -> Google_Ads | B33: =B22 -> 28184.51 | C33: =M22*$B$27-J22 -> 4227.6765 | D33: =C33/B33 -> 0.15 | E33: =B33+C33 -> 32412.186 | F33: =I22 -> INCREASE
A34: =A23 -> TikTok_Ads | B34: =B23 -> 37982.97 | C34: =M23*$B$27-J23 -> -17092.337 | D34: =C34/B34 -> -0.45 | E34: =B34+C34 -> 20890.633 | F34: =I23 -> DECREASE_HEAVY
A35: =A24 -> Email | B35: =B24 -> 1836.76 | C35: =M24*$B$27-J24 -> 275.514 | D35: =C35/B35 -> 0.15 | E35: =B35+C35 -> 2112.274 | F35: =I24 -> INCREASE
A36: Reserve (unallocated) | C36: =B28 -> 12589.146
A38: Method: Decreases (DECREASE_HEAVY -45%, DECREASE_LIGHT -25%) fund the freed budget. INCREASE channels split that budget proportionally to Net Profit, capped at the per-channel % above and at the total reallocation limit above; leftover is held as Reserve.

Sheet Funnel Analysis
A1: Funnel Analysis
A2: Click-through and conversion performance by channel, vs. historical benchmarks
A4: Channel | B4: Impressions | C4: Clicks | D4: Conversions | E4: CTR Actual | F4: CTR Benchmark | G4: CTR Diff (pp) | H4: CVR Actual | I4: CVR Benchmark | J4: CVR Diff (pp)
A5: Facebook_Ads | B5: =SUMIFS('Raw Data'!E2:E71,'Raw Data'!C2:C71,A5) -> 1941612 | C5: =SUMIFS('Raw Data'!F2:F71,'Raw Data'!C2:C71,A5) -> 51940 | D5: =SUMIFS('Raw Data'!G2:G71,'Raw Data'!C2:C71,A5) -> 1674 | E5: =IFERROR(C5/B5,"N/A") -> 0.026750968 | F5: 0.025 | G5: =IFERROR(E5-F5,"N/A") -> 0.0017509678 | H5: =IFERROR(D5/C5,"N/A") -> 0.032229496 | I5: 0.038 | J5: =IFERROR(H5-I5,"N/A") -> -0.0057705044
A6: Google_Ads | B6: =SUMIFS('Raw Data'!E2:E71,'Raw Data'!C2:C71,A6) -> 978780 | C6: =SUMIFS('Raw Data'!F2:F71,'Raw Data'!C2:C71,A6) -> 30613 | D6: =SUMIFS('Raw Data'!G2:G71,'Raw Data'!C2:C71,A6) -> 1651 | E6: =IFERROR(C6/B6,"N/A") -> 0.031276691 | F6: 0.05 | G6: =IFERROR(E6-F6,"N/A") -> -0.018723309 | H6: =IFERROR(D6/C6,"N/A") -> 0.053931336 | I6: 0.045 | J6: =IFERROR(H6-I6,"N/A") -> 0.0089313364
A7: TikTok_Ads | B7: =SUMIFS('Raw Data'!E2:E71,'Raw Data'!C2:C71,A7) -> 3260225 | C7: =SUMIFS('Raw Data'!F2:F71,'Raw Data'!C2:C71,A7) -> 63698 | D7: =SUMIFS('Raw Data'!G2:G71,'Raw Data'!C2:C71,A7) -> 663 | E7: =IFERROR(C7/B7,"N/A") -> 0.019537915 | F7: 0.02 | G7: =IFERROR(E7-F7,"N/A") -> -0.00046208467 | H7: =IFERROR(D7/C7,"N/A") -> 0.01040849 | I7: 0.009 | J7: =IFERROR(H7-I7,"N/A") -> 0.0014084901
A8: Email | B8: =SUMIFS('Raw Data'!E2:E71,'Raw Data'!C2:C71,A8) -> 0 | C8: =SUMIFS('Raw Data'!F2:F71,'Raw Data'!C2:C71,A8) -> 100213 | D8: =SUMIFS('Raw Data'!G2:G71,'Raw Data'!C2:C71,A8) -> 2335 | E8: =IFERROR(C8/B8,"N/A") -> N/A | F8: 0.15 | G8: =IFERROR(E8-F8,"N/A") -> N/A | H8: =IFERROR(D8/C8,"N/A") -> 0.02330037 | I8: 0.021 | J8: =IFERROR(H8-I8,"N/A") -> 0.0023003702
A10: Note: Email has no impression data, so CTR is N/A. Benchmark cells (blue) are editable assumptions.

Sheet Efficiency Analysis
A1: Efficiency Analysis
A2: Return, cost, and profitability performance by channel
A4: Assumptions
A5: Target ROAS (minimum) | B5: 4
A6: Max CPA | B6: 50
A7: Shipping Cost per Order | B7: 8
A8: Product Cost (% of Revenue) | B8: 0.35
A10: Channel | B10: Spend | C10: Revenue | D10: Conversions | E10: Orders | F10: ROAS | G10: ROAS Status | H10: CPA | I10: CPA Status | J10: Net Profit | K10: Net Profit Status
A11: Facebook_Ads | B11: =SUMIFS('Raw Data'!H2:H71,'Raw Data'!C2:C71,A11) -> 36678.01 | C11: =SUMIFS('Raw Data'!I2:I71,'Raw Data'!C2:C71,A11) -> 165482.75 | D11: =SUMIFS('Raw Data'!G2:G71,'Raw Data'!C2:C71,A11) -> 1674 | E11: =SUMIFS('Raw Data'!J2:J71,'Raw Data'!C2:C71,A11) -> 1674 | F11: =IFERROR(C11/B11,0) -> 4.5117701 | G11: =IF(F11>=$B$5,"Above","Below") -> Above | H11: =IFERROR(B11/D11,0) -> 21.9104 | I11: =IF(H11<=$B$6,"Below","Above") -> Below | J11: =C11-(B11+E11*$B$7+C11*$B$8) -> 57493.777 | K11: =IF(J11>0,"Positive","Negative") -> Positive
A12: Google_Ads | B12: =SUMIFS('Raw Data'!H2:H71,'Raw Data'!C2:C71,A12) -> 28184.51 | C12: =SUMIFS('Raw Data'!I2:I71,'Raw Data'!C2:C71,A12) -> 170414.87 | D12: =SUMIFS('Raw Data'!G2:G71,'Raw Data'!C2:C71,A12) -> 1651 | E12: =SUMIFS('Raw Data'!J2:J71,'Raw Data'!C2:C71,A12) -> 1651 | F12: =IFERROR(C12/B12,0) -> 6.0464017 | G12: =IF(F12>=$B$5,"Above","Below") -> Above | H12: =IFERROR(B12/D12,0) -> 17.071175 | I12: =IF(H12<=$B$6,"Below","Above") -> Below | J12: =C12-(B12+E12*$B$7+C12*$B$8) -> 69377.155 | K12: =IF(J12>0,"Positive","Negative") -> Positive
A13: TikTok_Ads | B13: =SUMIFS('Raw Data'!H2:H71,'Raw Data'!C2:C71,A13) -> 37982.97 | C13: =SUMIFS('Raw Data'!I2:I71,'Raw Data'!C2:C71,A13) -> 58447.71 | D13: =SUMIFS('Raw Data'!G2:G71,'Raw Data'!C2:C71,A13) -> 663 | E13: =SUMIFS('Raw Data'!J2:J71,'Raw Data'!C2:C71,A13) -> 663 | F13: =IFERROR(C13/B13,0) -> 1.5387873 | G13: =IF(F13>=$B$5,"Above","Below") -> Below | H13: =IFERROR(B13/D13,0) -> 57.289548 | I13: =IF(H13<=$B$6,"Below","Above") -> Above | J13: =C13-(B13+E13*$B$7+C13*$B$8) -> -5295.9585 | K13: =IF(J13>0,"Positive","Negative") -> Negative
A14: Email | B14: =SUMIFS('Raw Data'!H2:H71,'Raw Data'!C2:C71,A14) -> 1836.76 | C14: =SUMIFS('Raw Data'!I2:I71,'Raw Data'!C2:C71,A14) -> 237630.53 | D14: =SUMIFS('Raw Data'!G2:G71,'Raw Data'!C2:C71,A14) -> 2335 | E14: =SUMIFS('Raw Data'!J2:J71,'Raw Data'!C2:C71,A14) -> 2335 | F14: =IFERROR(C14/B14,0) -> 129.37484 | G14: =IF(F14>=$B$5,"Above","Below") -> Above | H14: =IFERROR(B14/D14,0) -> 0.78662099 | I14: =IF(H14<=$B$6,"Below","Above") -> Below | J14: =C14-(B14+E14*$B$7+C14*$B$8) -> 133943.08 | K14: =IF(J14>0,"Positive","Negative") -> Positive

Sheet Raw Data
A1: date | B1: campaign_name | C1: channel | D1: segment | E1: impressions | F1: clicks | G1: conversions | H1: spend | I1: revenue | J1: orders
A2: 2024-12-09 | B2: Holiday_Sale_Prospecting | C2: Facebook_Ads | D2: New_Customers | E2: 125279 | F2: 3169 | G2: 84 | H2: 2060.43 | I2: 7714.41 | J2: 84
A3: 2024-12-09 | B3: Holiday_Sale_Retargeting | C3: Facebook_Ads | D3: Retargeting | E3: 43118 | F3: 1724 | G3: 107 | H3: 1414.17 | I3: 11542.94 | J3: 107
A4: 2024-12-09 | B4: Product_Launch_Awareness | C4: Facebook_Ads | D4: New_Customers | E4: 96975 | F4: 2205 | G4: 38 | H4: 1544.07 | I4: 3371.63 | J4: 38
A5: 2024-12-09 | B5: Brand_Search | C5: Google_Ads | D5: New_Customers | E5: 15628 | F5: 775 | G5: 95 | H5: 813.82 | I5: 9750.01 | J5: 95
A6: 2024-12-09 | B6: Shopping_Campaigns | C6: Google_Ads | D6: New_Customers | E6: 77393 | F6: 1917 | G6: 57 | H6: 1629.03 | I6: 5306.69 | J6: 57
A7: 2024-12-09 | B7: Dynamic_Remarketing | C7: Google_Ads | D7: Retargeting | E7: 36298 | F7: 1366 | G7: 71 | H7: 1297.63 | I7: 7856.04 | J7: 71
A8: 2024-12-09 | B8: Influencer_Collab_Video | C8: TikTok_Ads | D8: New_Customers | E8: 244182 | F8: 4983 | G8: 47 | H8: 2890.61 | I8: 4057.74 | J8: 47
A9: 2024-12-09 | B9: UGC_Content_Campaign | C9: TikTok_Ads | D9: New_Customers | E9: 208784 | F9: 3839 | G9: 45 | H9: 2380.65 | I9: 4104.67 | J9: 45
A10: 2024-12-09 | B10: Weekly_Newsletter | C10: Email | D10: Loyalty | F10: 14001 | G10: 297 | H10: 279.3 | I10: 29050.54 | J10: 297
A11: 2024-12-09 | B11: Abandoned_Cart_Sequence | C11: Email | D11: Retargeting | F11: 2462 | G11: 84 | H11: 24.37 | I11: 9633.95 | J11: 84
A12: 2024-12-10 | B12: Holiday_Sale_Prospecting | C12: Facebook_Ads | D12: New_Customers | E12: 130163 | F12: 3293 | G12: 87 | H12: 2140.76 | I12: 8015.15 | J12: 87
A13: 2024-12-10 | B13: Holiday_Sale_Retargeting | C13: Facebook_Ads | D13: Retargeting | E13: 39463 | F13: 1578 | G13: 98 | H13: 1294.29 | I13: 10564.44 | J13: 98
A14: 2024-12-10 | B14: Product_Launch_Awareness | C14: Facebook_Ads | D14: New_Customers | E14: 98898 | F14: 2248 | G14: 39 | H14: 1574.69 | I14: 3438.51 | J14: 39
A15: 2024-12-10 | B15: Brand_Search | C15: Google_Ads | D15: New_Customers | E15: 17410 | F15: 863 | G15: 106 | H15: 906.65 | I15: 10862.09 | J15: 106
A16: 2024-12-10 | B16: Shopping_Campaigns | C16: Google_Ads | D16: New_Customers | E16: 93584 | F16: 2318 | G16: 69 | H16: 1969.82 | I16: 6416.83 | J16: 69
A17: 2024-12-10 | B17: Dynamic_Remarketing | C17: Google_Ads | D17: Retargeting | E17: 39271 | F17: 1478 | G17: 76 | H17: 1403.91 | I17: 8499.46 | J17: 76
A18: 2024-12-10 | B18: Influencer_Collab_Video | C18: TikTok_Ads | D18: New_Customers | E18: 290292 | F18: 5924 | G18: 56 | H18: 3436.45 | I18: 4823.97 | J18: 56
A19: 2024-12-10 | B19: UGC_Content_Campaign | C19: TikTok_Ads | D19: New_Customers | E19: 218783 | F19: 4023 | G19: 47 | H19: 2494.66 | I19: 4301.25 | J19: 47
A20: 2024-12-10 | B20: Weekly_Newsletter | C20: Email | D20: Loyalty | F20: 11265 | G20: 239 | H20: 224.73 | I20: 23374.21 | J20: 239
A21: 2024-12-10 | B21: Abandoned_Cart_Sequence | C21: Email | D21: Retargeting | F21: 2466 | G21: 84 | H21: 24.41 | I21: 9647.44 | J21: 84
A22: 2024-12-11 | B22: Holiday_Sale_Prospecting | C22: Facebook_Ads | D22: New_Customers | E22: 141306 | F22: 3575 | G22: 94 | H22: 2324.03 | I22: 8701.33 | J22: 94
A23: 2024-12-11 | B23: Holiday_Sale_Retargeting | C23: Facebook_Ads | D23: Retargeting | E23: 43932 | F23: 1756 | G23: 109 | H23: 1440.86 | I23: 11760.85 | J23: 109
A24: 2024-12-11 | B24: Product_Launch_Awareness | C24: Facebook_Ads | D24: New_Customers | E24: 86612 | F24: 1969 | G24: 34 | H24: 1379.06 | I24: 3011.33 | J24: 34
A25: 2024-12-11 | B25: Brand_Search | C25: Google_Ads | D25: New_Customers | E25: 14422 | F25: 715 | G25: 87 | H25: 751.06 | I25: 8998.08 | J25: 87
A26: 2024-12-11 | B26: Shopping_Campaigns | C26: Google_Ads | D26: New_Customers | E26: 80728 | F26: 1999 | G26: 59 | H26: 1699.22 | I26: 5535.35 | J26: 59
A27: 2024-12-11 | B27: Dynamic_Remarketing | C27: Google_Ads | D27: Retargeting | E27: 41764 | F27: 1571 | G27: 81 | H27: 1493.05 | I27: 9039.09 | J27: 81
A28: 2024-12-11 | B28: Influencer_Collab_Video | C28: TikTok_Ads | D28: New_Customers | E28: 288988 | F28: 5898 | G28: 56 | H28: 3421.01 | I28: 4802.29 | J28: 56
A29: 2024-12-11 | B29: UGC_Content_Campaign | C29: TikTok_Ads | D29: New_Customers | E29: 179785 | F29: 3306 | G29: 39 | H29: 2049.99 | I29: 3534.55 | J29: 39
A30: 2024-12-11 | B30: Weekly_Newsletter | C30: Email | D30: Loyalty | F30: 11140 | G30: 237 | H30: 222.24 | I30: 23115.38 | J30: 237
A31: 2024-12-11 | B31: Abandoned_Cart_Sequence | C31: Email | D31: Retargeting | F31: 2121 | G31: 72 | H31: 21 | I31: 8298.95 | J31: 72
A32: 2024-12-12 | B32: Holiday_Sale_Prospecting | C32: Facebook_Ads | D32: New_Customers | E32: 138154 | F32: 3495 | G32: 92 | H32: 2272.19 | I32: 8507.24 | J32: 92
A33: 2024-12-12 | B33: Holiday_Sale_Retargeting | C33: Facebook_Ads | D33: Retargeting | E33: 46835 | F33: 1873 | G33: 117 | H33: 1536.08 | I33: 12538.07 | J33: 117
A34: 2024-12-12 | B34: Product_Launch_Awareness | C34: Facebook_Ads | D34: New_Customers | E34: 95435 | F34: 2170 | G34: 37 | H34: 1519.55 | I34: 3318.1 | J34: 37
A35: 2024-12-12 | B35: Brand_Search | C35: Google_Ads | D35: New_Customers | E35: 15136 | F35: 750 | G35: 92 | H35: 788.21 | I35: 9443.2 | J35: 92
A36: 2024-12-12 | B36: Shopping_Campaigns | C36: Google_Ads | D36: New_Customers | E36: 79650 | F36: 1973 | G36: 58 | H36: 1676.54 | I36: 5461.45 | J36: 58
A37: 2024-12-12 | B37: Dynamic_Remarketing | C37: Google_Ads | D37: Retargeting | E37: 37349 | F37: 1405 | G37: 73 | H37: 1335.19 | I37: 8083.42 | J37: 73
A38: 2024-12-12 | B38: Influencer_Collab_Video | C38: TikTok_Ads | D38: New_Customers | E38: 242963 | F38: 4958 | G38: 47 | H38: 2876.18 | I38: 4037.48 | J38: 47
A39: 2024-12-12 | B39: UGC_Content_Campaign | C39: TikTok_Ads | D39: New_Customers | E39: 220333 | F39: 4051 | G39: 48 | H39: 2512.33 | I39: 4331.72 | J39: 48
A40: 2024-12-12 | B40: Weekly_Newsletter | C40: Email | D40: Loyalty | F40: 11610 | G40: 247 | H40: 231.6 | I40: 24089.32 | J40: 247
...
